Traceback (most recent call last):
  File "/Users/clemens10/miniconda3/lib/python3.7/site-packages/jupyter_cache/executors/utils.py", line 56, in single_nb_execution
    record_timing=False,
  File "/Users/clemens10/miniconda3/lib/python3.7/site-packages/nbclient/client.py", line 1112, in execute
    return NotebookClient(nb=nb, resources=resources, km=km, **kwargs).execute()
  File "/Users/clemens10/miniconda3/lib/python3.7/site-packages/nbclient/util.py", line 74, in wrapped
    return just_run(coro(*args, **kwargs))
  File "/Users/clemens10/miniconda3/lib/python3.7/site-packages/nbclient/util.py", line 53, in just_run
    return loop.run_until_complete(coro)
  File "/Users/clemens10/miniconda3/lib/python3.7/asyncio/base_events.py", line 583, in run_until_complete
    return future.result()
  File "/Users/clemens10/miniconda3/lib/python3.7/site-packages/nbclient/client.py", line 554, in async_execute
    cell, index, execution_count=self.code_cells_executed + 1
  File "/Users/clemens10/miniconda3/lib/python3.7/site-packages/nbclient/client.py", line 857, in async_execute_cell
    self._check_raise_for_error(cell, exec_reply)
  File "/Users/clemens10/miniconda3/lib/python3.7/site-packages/nbclient/client.py", line 760, in _check_raise_for_error
    raise CellExecutionError.from_cell_and_msg(cell, exec_reply_content)
nbclient.exceptions.CellExecutionError: An error occurred while executing the following cell:
------------------
load_results = False
if load_results and os.path.exists(save_name + '_results.h5'):
    print(f'loading results file produced at the end of training.')
    datasets = das.utils.load_from(save_name + '_results.h5', ['x_test', 'y_test', 'y_pred'])
    x_test, y_test, y_pred = [datasets[key] for key in ['x_test', 'y_test', 'y_pred']]  # unpack dict items to vars
    # predict events and segments from loaded confidence scores
    events, segments = das.predict.predict_song(y_pred, params, 
                        segment_minlen=0.02, segment_fillgap=0.02)
else:
    # Load training data set - path is in params['data_dir']. If you trained on a different machine set a custom path 
    params['data_dir'] = '/Users/clemens10/Dropbox/dss.paper/dat/dmel_single_stern_raw.npy'
    data = das.io.load(params['data_dir'])
    x_test = data['test']['x']
    y_test = data['test']['y'].astype(np.float)
    # create confidence scores by running the models and predict events and segments
    events, segments, y_pred = das.predict.predict(x_test, model_save_name=save_name, verbose=1, batch_size=1, segment_minlen=0.02, segment_fillgap=0.02)

------------------

[0;31m---------------------------------------------------------------------------[0m
[0;31mValueError[0m                                Traceback (most recent call last)
[0;32m<ipython-input-3-1138d666c794>[0m in [0;36m<module>[0;34m[0m
[1;32m     14[0m     [0my_test[0m [0;34m=[0m [0mdata[0m[0;34m[[0m[0;34m'test'[0m[0;34m][0m[0;34m[[0m[0;34m'y'[0m[0;34m][0m[0;34m.[0m[0mastype[0m[0;34m([0m[0mnp[0m[0;34m.[0m[0mfloat[0m[0;34m)[0m[0;34m[0m[0;34m[0m[0m
[1;32m     15[0m     [0;31m# create confidence scores by running the models and predict events and segments[0m[0;34m[0m[0;34m[0m[0;34m[0m[0m
[0;32m---> 16[0;31m     [0mevents[0m[0;34m,[0m [0msegments[0m[0;34m,[0m [0my_pred[0m [0;34m=[0m [0mdas[0m[0;34m.[0m[0mpredict[0m[0;34m.[0m[0mpredict[0m[0;34m([0m[0mx_test[0m[0;34m,[0m [0mmodel_save_name[0m[0;34m=[0m[0msave_name[0m[0;34m,[0m [0mverbose[0m[0;34m=[0m[0;36m1[0m[0;34m,[0m [0mbatch_size[0m[0;34m=[0m[0;36m1[0m[0;34m,[0m [0msegment_minlen[0m[0;34m=[0m[0;36m0.02[0m[0;34m,[0m [0msegment_fillgap[0m[0;34m=[0m[0;36m0.02[0m[0;34m)[0m[0;34m[0m[0;34m[0m[0m
[0m
[0;31mValueError[0m: too many values to unpack (expected 3)
ValueError: too many values to unpack (expected 3)

